<!DOCTYPE html>
<html lang="en">

  <head>
    <meta charset="UTF-8">
    <meta name="viewport" content="width=device-width, initial-scale=1.0">
    <meta http-equiv="X-UA-Compatible" content="ie=edge">
    <title>Document</title>
  </head>

  <body>
    <script>
      function after(times, cb) {
        return function () {
          --times == 0 && cb.apply(null, arguments);
        }
      }
      console.log(1)
      var p = new Promise((resolve, reject) => {
        console.log(2)
        resolve(3)
      })
      p.then((params) => {
        console.log(params)
      })
      console.log(4)
      // 1 2 4 3
      // Promise内部代码同步执行，异步执行的只是then里的代码

      var p2 = new Promise((a, b) => {
        console.log('p2');
        b()
      })
      p2.then(() => {
        console.log('p2Suc')
      }, () => {
        console.log('p2Fail')
      }).then(() => {
        console.log('p2ThenSuc')
      }, () => {
        console.log('p2ThenFail')
      })
      // p2 p2Fail p2ThenSuc
      // then没有显示返回值时返回的是一个新的Promise，而且会是resolve状态；

      var p3 = new Promise((a, b) => {
        a()
      })
      p3.then(() => {
        throw new Error('rafer')
      }).then().then(() => {}).then(null, (err) => {
        console.log(111, err); // 会进入111这里，当没有这个reject函数时，就会走catch98里面
      }).catch((err) => {
        console.log(98, err)
        return 10
      }).then((val) => { // 虽然前面有错误而且捕获到了，但是这里仍然会执行
        console.log('catchThen', val)
      }).finally(() => { // 无论前面resolve或reject，这里都会执行
        console.log('over')
      }).then(() => {
        console.log(666)
      })
      // 111, Error:rafer
      // catchThen,  undefined
      // over
      // 666
      // 当then里没执行代码时，相当于没写，如then().then(() => {})
      // 当发生错误时，后续距离最近的reject函数或catch都可以捕获到，而且如果后续还有then时也会执行；
      // 遇到finally时，无论前面是成功还是失败都会执行，也就是不用像then一样写两个函数reject和resolve回调
      // finally后面有then时，也会继续执行
    </script>
  </body>

</html>